Traceback (most recent call last):
  File "/home/kartushov/pet_projects/RLTPS/venv/lib/python3.9/site-packages/pandas/core/indexes/base.py", line 3621, in get_loc
    return self._engine.get_loc(casted_key)
  File "pandas/_libs/index.pyx", line 136, in pandas._libs.index.IndexEngine.get_loc
  File "pandas/_libs/index.pyx", line 163, in pandas._libs.index.IndexEngine.get_loc
  File "pandas/_libs/hashtable_class_helper.pxi", line 5198, in pandas._libs.hashtable.PyObjectHashTable.get_item
  File "pandas/_libs/hashtable_class_helper.pxi", line 5206, in pandas._libs.hashtable.PyObjectHashTable.get_item
KeyError: 'mean'
The above exception was the direct cause of the following exception:
Traceback (most recent call last):
  File "/home/kartushov/pet_projects/RLTPS/gen_deap.py", line 86, in <module>
    wandb_register(logbook)
  File "/home/kartushov/pet_projects/RLTPS/gen_deap.py", line 76, in wandb_register
    'mean': result_df.loc['mean', i],
  File "/home/kartushov/pet_projects/RLTPS/venv/lib/python3.9/site-packages/pandas/core/indexing.py", line 960, in __getitem__
    return self.obj._get_value(*key, takeable=self._takeable)
  File "/home/kartushov/pet_projects/RLTPS/venv/lib/python3.9/site-packages/pandas/core/frame.py", line 3622, in _get_value
    row = self.index.get_loc(index)
  File "/home/kartushov/pet_projects/RLTPS/venv/lib/python3.9/site-packages/pandas/core/indexes/base.py", line 3623, in get_loc
    raise KeyError(key) from err
KeyError: 'mean'